[2023-11-20 17:34:00,527: INFO: main: Welcome to a custome log]
[2023-11-20 20:45:23,377: INFO: main: Welcome to a custome log]
[2023-11-20 20:47:07,945: INFO: main: Welcome to a custome log]
[2023-11-20 20:49:15,201: INFO: main: Welcome to a custome log]
[2023-11-20 20:49:23,223: INFO: main: Welcome to a custome log]
<<<<<<< HEAD
[2023-11-22 14:23:12,952: INFO: main: >>>>>> stage Data Ingestion stage started <<<<<<]
[2023-11-22 14:23:12,952: INFO: common: yaml file: config\config.yaml loaded successfully]
[2023-11-22 14:23:12,952: INFO: common: yaml file: params.yaml loaded successfully]
[2023-11-22 14:23:12,952: ERROR: main: yaml file is empty]
Traceback (most recent call last):
  File "c:\users\juanc\onedrive\escritorio\heart-disease-predictor\src\cnnClassifier\utils\common.py", line 33, in read_yaml
    return ConfigBox(content)
           ^^^^^^^^^^^^^^^^^^
  File "C:\Users\juanc\anaconda3\Lib\site-packages\box\box.py", line 259, in __init__
    raise BoxValueError("First argument must be mapping or iterable")
box.exceptions.BoxValueError: First argument must be mapping or iterable

During handling of the above exception, another exception occurred:

Traceback (most recent call last):
  File "C:\Users\juanc\OneDrive\Escritorio\heart-disease-predictor\main.py", line 8, in <module>
    data_ingestion.main()
  File "c:\users\juanc\onedrive\escritorio\heart-disease-predictor\src\cnnClassifier\pipeline\stage_01_data_ingestion.py", line 13, in main
    config = ConfigurationManager()
             ^^^^^^^^^^^^^^^^^^^^^^
  File "c:\users\juanc\onedrive\escritorio\heart-disease-predictor\src\cnnClassifier\config\configuration.py", line 13, in __init__
    self.params = read_yaml(params_filepath)
                  ^^^^^^^^^^^^^^^^^^^^^^^^^^
  File "C:\Users\juanc\anaconda3\Lib\site-packages\ensure\main.py", line 849, in __call__
    return_val = self.f(*args, **kwargs)
                 ^^^^^^^^^^^^^^^^^^^^^^^
  File "c:\users\juanc\onedrive\escritorio\heart-disease-predictor\src\cnnClassifier\utils\common.py", line 35, in read_yaml
    raise ValueError("yaml file is empty")
ValueError: yaml file is empty
[2023-11-22 14:24:24,028: INFO: main: >>>>>> stage Data Ingestion stage started <<<<<<]
[2023-11-22 14:24:24,028: INFO: common: yaml file: config\config.yaml loaded successfully]
[2023-11-22 14:24:24,039: INFO: common: yaml file: params.yaml loaded successfully]
[2023-11-22 14:24:24,039: INFO: common: created directory at: artifacts]
[2023-11-22 14:24:24,039: INFO: common: created directory at: artifacts/data_ingestion]
[2023-11-22 14:24:24,042: INFO: data_ingestion: Downloading data from https://drive.google.com/file/d/1skMXfSObiyb4ZQy07CdFYQjdz4qCpjDK/view?usp=sharing into file artifacts/data_ingestion/data.zip]
[2023-11-22 14:24:39,999: INFO: data_ingestion: Downloaded data from https://drive.google.com/file/d/1skMXfSObiyb4ZQy07CdFYQjdz4qCpjDK/view?usp=sharing into file artifacts/data_ingestion/data.zip]
[2023-11-22 14:24:49,017: INFO: main: >>>>>> stage Data Ingestion stage completed <<<<<<

x==========x]
=======
>>>>>>> 6c6d947c62a0a76da70ca57e298604ada97527c6
[2023-11-22 21:36:43,227: INFO: main: >>>>>> stage Data Ingestion stage started <<<<<<]
[2023-11-22 21:36:43,229: INFO: common: yaml file: config\config.yaml loaded successfully]
[2023-11-22 21:36:43,232: INFO: common: yaml file: params.yaml loaded successfully]
[2023-11-22 21:36:43,233: INFO: common: created directory at: artifacts]
[2023-11-22 21:36:43,234: INFO: common: created directory at: artifacts/data_ingestion]
[2023-11-22 21:36:43,234: INFO: data_ingestion: Downloading data from https://drive.google.com/file/d/1skMXfSObiyb4ZQy07CdFYQjdz4qCpjDK/view?usp=sharing into file artifacts/data_ingestion/data.zip]
[2023-11-22 21:36:56,301: INFO: data_ingestion: Downloaded data from https://drive.google.com/file/d/1skMXfSObiyb4ZQy07CdFYQjdz4qCpjDK/view?usp=sharing into file artifacts/data_ingestion/data.zip]
[2023-11-22 21:37:05,516: INFO: main: >>>>>> stage Data Ingestion stage completed <<<<<<

x==========x]
[2023-11-22 21:37:05,516: INFO: main: Welcome to a custome log]
[2023-11-22 21:37:05,516: INFO: main: *******************]
[2023-11-22 21:37:05,516: INFO: main: >>>>>> stage Prepare base model started <<<<<<]
[2023-11-22 21:37:05,516: ERROR: main: name 'PrepareBaseModelTrainingPipeline' is not defined]
Traceback (most recent call last):
  File "C:\Users\juanc\OneDrive\Escritorio\heart-disease-predictor\main.py", line 23, in <module>
    prepare_base_model = PrepareBaseModelTrainingPipeline()
                         ^^^^^^^^^^^^^^^^^^^^^^^^^^^^^^^^
NameError: name 'PrepareBaseModelTrainingPipeline' is not defined
[2023-11-22 21:44:03,464: INFO: main: >>>>>> stage Data Ingestion stage started <<<<<<]
[2023-11-22 21:44:03,464: INFO: common: yaml file: config\config.yaml loaded successfully]
[2023-11-22 21:44:03,464: INFO: common: yaml file: params.yaml loaded successfully]
[2023-11-22 21:44:03,464: INFO: common: created directory at: artifacts]
[2023-11-22 21:44:03,464: INFO: common: created directory at: artifacts/data_ingestion]
[2023-11-22 21:44:03,464: INFO: data_ingestion: Downloading data from https://drive.google.com/file/d/1skMXfSObiyb4ZQy07CdFYQjdz4qCpjDK/view?usp=sharing into file artifacts/data_ingestion/data.zip]
[2023-11-22 21:44:20,578: INFO: data_ingestion: Downloaded data from https://drive.google.com/file/d/1skMXfSObiyb4ZQy07CdFYQjdz4qCpjDK/view?usp=sharing into file artifacts/data_ingestion/data.zip]
[2023-11-22 21:44:30,062: INFO: main: >>>>>> stage Data Ingestion stage completed <<<<<<

x==========x]
[2023-11-22 21:44:30,062: INFO: main: Welcome to a custome log]
[2023-11-22 21:44:30,062: INFO: main: *******************]
[2023-11-22 21:44:30,062: INFO: main: >>>>>> stage Prepare base model started <<<<<<]
[2023-11-22 21:44:30,064: INFO: common: yaml file: config\config.yaml loaded successfully]
[2023-11-22 21:44:30,064: INFO: common: yaml file: params.yaml loaded successfully]
[2023-11-22 21:44:30,064: INFO: common: created directory at: artifacts]
[2023-11-22 21:44:30,064: ERROR: main: "'ConfigBox' object has no attribute 'prepare_base_model'"]
Traceback (most recent call last):
  File "C:\Users\juanc\anaconda3\Lib\site-packages\box\box.py", line 503, in __getitem__
    return super().__getitem__(item)
           ^^^^^^^^^^^^^^^^^^^^^^^^^
KeyError: 'prepare_base_model'

The above exception was the direct cause of the following exception:

Traceback (most recent call last):
  File "C:\Users\juanc\anaconda3\Lib\site-packages\box\box.py", line 536, in __getattr__
    value = self.__getitem__(item, _ignore_default=True)
            ^^^^^^^^^^^^^^^^^^^^^^^^^^^^^^^^^^^^^^^^^^^^
  File "C:\Users\juanc\anaconda3\Lib\site-packages\box\box.py", line 524, in __getitem__
    raise BoxKeyError(str(err)) from _exception_cause(err)
box.exceptions.BoxKeyError: "'prepare_base_model'"

During handling of the above exception, another exception occurred:

Traceback (most recent call last):
  File "C:\Users\juanc\anaconda3\Lib\site-packages\box\box.py", line 538, in __getattr__
    value = object.__getattribute__(self, item)
            ^^^^^^^^^^^^^^^^^^^^^^^^^^^^^^^^^^^
AttributeError: 'ConfigBox' object has no attribute 'prepare_base_model'

The above exception was the direct cause of the following exception:

Traceback (most recent call last):
  File "C:\Users\juanc\anaconda3\Lib\site-packages\box\config_box.py", line 28, in __getattr__
    return super().__getattr__(item)
           ^^^^^^^^^^^^^^^^^^^^^^^^^
  File "C:\Users\juanc\anaconda3\Lib\site-packages\box\box.py", line 552, in __getattr__
    raise BoxKeyError(str(err)) from _exception_cause(err)
box.exceptions.BoxKeyError: "'ConfigBox' object has no attribute 'prepare_base_model'"

During handling of the above exception, another exception occurred:

Traceback (most recent call last):
  File "C:\Users\juanc\anaconda3\Lib\site-packages\box\box.py", line 503, in __getitem__
    return super().__getitem__(item)
           ^^^^^^^^^^^^^^^^^^^^^^^^^
KeyError: 'prepare_base_model'

The above exception was the direct cause of the following exception:

Traceback (most recent call last):
  File "C:\Users\juanc\anaconda3\Lib\site-packages\box\box.py", line 536, in __getattr__
    value = self.__getitem__(item, _ignore_default=True)
            ^^^^^^^^^^^^^^^^^^^^^^^^^^^^^^^^^^^^^^^^^^^^
  File "C:\Users\juanc\anaconda3\Lib\site-packages\box\box.py", line 524, in __getitem__
    raise BoxKeyError(str(err)) from _exception_cause(err)
box.exceptions.BoxKeyError: "'prepare_base_model'"

During handling of the above exception, another exception occurred:

Traceback (most recent call last):
  File "C:\Users\juanc\anaconda3\Lib\site-packages\box\box.py", line 538, in __getattr__
    value = object.__getattribute__(self, item)
            ^^^^^^^^^^^^^^^^^^^^^^^^^^^^^^^^^^^
AttributeError: 'ConfigBox' object has no attribute 'prepare_base_model'

The above exception was the direct cause of the following exception:

Traceback (most recent call last):
  File "C:\Users\juanc\OneDrive\Escritorio\heart-disease-predictor\main.py", line 25, in <module>
    prepare_base_model.main()
  File "c:\users\juanc\onedrive\escritorio\heart-disease-predictor\src\cnnClassifier\pipeline\stage_02_prepare_base_model.py", line 15, in main
    prepare_base_model_config = config.get_prepare_base_model_config()
                                ^^^^^^^^^^^^^^^^^^^^^^^^^^^^^^^^^^^^^^
  File "c:\users\juanc\onedrive\escritorio\heart-disease-predictor\src\cnnClassifier\config\configuration.py", line 34, in get_prepare_base_model_config
    config = self.config.prepare_base_model
             ^^^^^^^^^^^^^^^^^^^^^^^^^^^^^^
  File "C:\Users\juanc\anaconda3\Lib\site-packages\box\config_box.py", line 30, in __getattr__
    return super().__getattr__(item.lower())
           ^^^^^^^^^^^^^^^^^^^^^^^^^^^^^^^^^
  File "C:\Users\juanc\anaconda3\Lib\site-packages\box\box.py", line 552, in __getattr__
    raise BoxKeyError(str(err)) from _exception_cause(err)
box.exceptions.BoxKeyError: "'ConfigBox' object has no attribute 'prepare_base_model'"
[2023-11-22 21:50:22,766: INFO: main: >>>>>> stage Data Ingestion stage started <<<<<<]
[2023-11-22 21:50:22,766: INFO: common: yaml file: config\config.yaml loaded successfully]
[2023-11-22 21:50:22,766: INFO: common: yaml file: params.yaml loaded successfully]
[2023-11-22 21:50:22,766: INFO: common: created directory at: artifacts]
[2023-11-22 21:50:22,766: INFO: common: created directory at: artifacts/data_ingestion]
[2023-11-22 21:50:22,766: INFO: data_ingestion: Downloading data from https://drive.google.com/file/d/1skMXfSObiyb4ZQy07CdFYQjdz4qCpjDK/view?usp=sharing into file artifacts/data_ingestion/data.zip]
[2023-11-22 21:50:42,456: INFO: data_ingestion: Downloaded data from https://drive.google.com/file/d/1skMXfSObiyb4ZQy07CdFYQjdz4qCpjDK/view?usp=sharing into file artifacts/data_ingestion/data.zip]
[2023-11-22 21:50:50,279: INFO: main: >>>>>> stage Data Ingestion stage completed <<<<<<

x==========x]
[2023-11-22 21:50:50,279: INFO: main: Welcome to a custome log]
[2023-11-22 21:50:50,282: INFO: main: *******************]
[2023-11-22 21:50:50,282: INFO: main: >>>>>> stage Prepare base model started <<<<<<]
[2023-11-22 21:50:50,282: INFO: common: yaml file: config\config.yaml loaded successfully]
[2023-11-22 21:50:50,282: INFO: common: yaml file: params.yaml loaded successfully]
[2023-11-22 21:50:50,282: INFO: common: created directory at: artifacts]
[2023-11-22 21:50:50,325: INFO: common: created directory at: artifacts/prepare_base_model]
[2023-11-22 21:50:54,935: WARNING: saving_utils: Compiled the loaded model, but the compiled metrics have yet to be built. `model.compile_metrics` will be empty until you train or evaluate the model.]
[2023-11-22 21:50:55,587: INFO: main: >>>>>> stage Prepare base model completed <<<<<<

x==========x]
