[2023-11-20 17:34:00,527: INFO: main: Welcome to a custome log]
[2023-11-20 20:45:23,377: INFO: main: Welcome to a custome log]
[2023-11-20 20:47:07,945: INFO: main: Welcome to a custome log]
[2023-11-20 20:49:15,201: INFO: main: Welcome to a custome log]
[2023-11-20 20:49:23,223: INFO: main: Welcome to a custome log]
<<<<<<< HEAD
[2023-11-22 14:23:12,952: INFO: main: >>>>>> stage Data Ingestion stage started <<<<<<]
[2023-11-22 14:23:12,952: INFO: common: yaml file: config\config.yaml loaded successfully]
[2023-11-22 14:23:12,952: INFO: common: yaml file: params.yaml loaded successfully]
[2023-11-22 14:23:12,952: ERROR: main: yaml file is empty]
Traceback (most recent call last):
  File "c:\users\juanc\onedrive\escritorio\heart-disease-predictor\src\cnnClassifier\utils\common.py", line 33, in read_yaml
    return ConfigBox(content)
           ^^^^^^^^^^^^^^^^^^
  File "C:\Users\juanc\anaconda3\Lib\site-packages\box\box.py", line 259, in __init__
    raise BoxValueError("First argument must be mapping or iterable")
box.exceptions.BoxValueError: First argument must be mapping or iterable

During handling of the above exception, another exception occurred:

Traceback (most recent call last):
  File "C:\Users\juanc\OneDrive\Escritorio\heart-disease-predictor\main.py", line 8, in <module>
    data_ingestion.main()
  File "c:\users\juanc\onedrive\escritorio\heart-disease-predictor\src\cnnClassifier\pipeline\stage_01_data_ingestion.py", line 13, in main
    config = ConfigurationManager()
             ^^^^^^^^^^^^^^^^^^^^^^
  File "c:\users\juanc\onedrive\escritorio\heart-disease-predictor\src\cnnClassifier\config\configuration.py", line 13, in __init__
    self.params = read_yaml(params_filepath)
                  ^^^^^^^^^^^^^^^^^^^^^^^^^^
  File "C:\Users\juanc\anaconda3\Lib\site-packages\ensure\main.py", line 849, in __call__
    return_val = self.f(*args, **kwargs)
                 ^^^^^^^^^^^^^^^^^^^^^^^
  File "c:\users\juanc\onedrive\escritorio\heart-disease-predictor\src\cnnClassifier\utils\common.py", line 35, in read_yaml
    raise ValueError("yaml file is empty")
ValueError: yaml file is empty
[2023-11-22 14:24:24,028: INFO: main: >>>>>> stage Data Ingestion stage started <<<<<<]
[2023-11-22 14:24:24,028: INFO: common: yaml file: config\config.yaml loaded successfully]
[2023-11-22 14:24:24,039: INFO: common: yaml file: params.yaml loaded successfully]
[2023-11-22 14:24:24,039: INFO: common: created directory at: artifacts]
[2023-11-22 14:24:24,039: INFO: common: created directory at: artifacts/data_ingestion]
[2023-11-22 14:24:24,042: INFO: data_ingestion: Downloading data from https://drive.google.com/file/d/1skMXfSObiyb4ZQy07CdFYQjdz4qCpjDK/view?usp=sharing into file artifacts/data_ingestion/data.zip]
[2023-11-22 14:24:39,999: INFO: data_ingestion: Downloaded data from https://drive.google.com/file/d/1skMXfSObiyb4ZQy07CdFYQjdz4qCpjDK/view?usp=sharing into file artifacts/data_ingestion/data.zip]
[2023-11-22 14:24:49,017: INFO: main: >>>>>> stage Data Ingestion stage completed <<<<<<

x==========x]
=======
>>>>>>> 6c6d947c62a0a76da70ca57e298604ada97527c6
